Workbook

Sheet Ellora Electricity Billing
G2: Monthly Consumption & Billing
H3: ELLORA PROPERTY SERVICES PVT. LTD.
H4: Electricity Charges for the Month of Nov 2020 | P4: Partywise Electicty Cahrges
B5: Sr.no. | C5: Customer Name | D5: Hospital LT | E5: Bungalow 1 LT Panel | F5: Office Set LT Panel | G5: Police Station | H5: 8000 Sqft | I5: Restaurant | J5: Parsi | K5: Bungalow 2 LT | L5: Villa | M5: ODU | N5: Total
B6: 1 | C6: Balaji Telefilms Ltd | D6: =Summary!F17 -> 0 | E6: =Summary!H17 -> 0 | F6: =Summary!J17 -> 0 | G6: =Summary!K17 -> 73 | H6: =Summary!L17 -> 0 | I6: =Summary!M17 -> 0 | J6: =Summary!N17+Summary!O17 -> 0 | K6: =Summary!P17 -> 0 | L6: =Summary!Q17+Summary!R17 -> 0 | M6: =Summary!G17+Summary!I17+Summary!S17+Summary!T17+Summary!U17 -> 0 | N6: =SUM(D6:M6) -> 73 | P6: Daily Readings
B7: 2 | C7: Bambai Dreams Entertainment (Opc) Private Limited | D7: =Summary!F18 -> 368 | E7: =Summary!H18 -> 0 | F7: =Summary!J18 -> 0 | G7: =Summary!K18 -> 0 | H7: =Summary!L18 -> 0 | I7: =Summary!M18 -> 0 | J7: =Summary!N18+Summary!O18 -> 0 | K7: =Summary!P18 -> 0 | L7: =Summary!Q18+Summary!R18 -> 0 | M7: =Summary!G18+Summary!I18+Summary!S18+Summary!T18+Summary!U18 -> 0 | N7: =SUM(D7:M7) -> 368 | P7: Daily Readings - Makeup Room
B8: 3 | C8: Boathouse Media Private Limited | D8: =Summary!F19 -> 0 | E8: =Summary!H19 -> 620 | F8: =Summary!J19 -> 0 | G8: =Summary!K19 -> 0 | H8: =Summary!L19 -> 0 | I8: =Summary!M19 -> 0 | J8: =Summary!N19+Summary!O19 -> 0 | K8: =Summary!P19 -> 0 | L8: =Summary!Q19+Summary!R19 -> 0 | M8: =Summary!G19+Summary!I19+Summary!S19+Summary!T19+Summary!U19 -> 0 | N8: =SUM(D8:M8) -> 620 | P8: Unit Consumption Details
B9: 4 | C9: Classic Films | D9: =Summary!F20 -> 0 | E9: =Summary!H20 -> 692 | F9: =Summary!J20 -> 0 | G9: =Summary!K20 -> 0 | H9: =Summary!L20 -> 0 | I9: =Summary!M20 -> 0 | J9: =Summary!N20+Summary!O20 -> 0 | K9: =Summary!P20 -> 1954 | L9: =Summary!Q20+Summary!R20 -> 0 | M9: =Summary!G20+Summary!I20+Summary!S20+Summary!T20+Summary!U20 -> 0 | N9: =SUM(D9:M9) -> 2646 | P9: Monthly LT Panel Summary
B10: 5 | C10: Contiloe Pictures Pvt Ltd. | D10: =Summary!F21 -> 0 | E10: =Summary!H21 -> 0 | F10: =Summary!J21 -> 0 | G10: =Summary!K21 -> 0 | H10: =Summary!L21 -> 0 | I10: =Summary!M21 -> 0 | J10: =Summary!N21+Summary!O21 -> 0 | K10: =Summary!P21 -> 0 | L10: =Summary!Q21+Summary!R21 -> 0 | M10: =Summary!G21+Summary!I21+Summary!S21+Summary!T21+Summary!U21 -> 0 | N10: =SUM(D10:M10) -> 0
B11: 6 | C11: Dashmi Creations LLP | D11: =Summary!F22 -> 173 | E11: =Summary!H22 -> 116 | F11: =Summary!J22 -> 0 | G11: =Summary!K22 -> 86 | H11: =Summary!L22 -> 0 | I11: =Summary!M22 -> 39 | J11: =Summary!N22+Summary!O22 -> 0 | K11: =Summary!P22 -> 0 | L11: =Summary!Q22+Summary!R22 -> 0 | M11: =Summary!G22+Summary!I22+Summary!S22+Summary!T22+Summary!U22 -> 0 | N11: =SUM(D11:M11) -> 414
B12: 7 | C12: Essel Vision Production Ltd. | D12: =Summary!F23 -> 486 | E12: =Summary!H23 -> 0 | F12: =Summary!J23 -> 0 | G12: =Summary!K23 -> 0 | H12: =Summary!L23 -> 0 | I12: =Summary!M23 -> 0 | J12: =Summary!N23+Summary!O23 -> 0 | K12: =Summary!P23 -> 0 | L12: =Summary!Q23+Summary!R23 -> 1776 | M12: =Summary!G23+Summary!I23+Summary!S23+Summary!T23+Summary!U23 -> 304 | N12: =SUM(D12:M12) -> 2566
B13: 8 | C13: Fanboy Pictures Private Limited | D13: =Summary!F24 -> 0 | E13: =Summary!H24 -> 720 | F13: =Summary!J24 -> 47 | G13: =Summary!K24 -> 130 | H13: =Summary!L24 -> 0 | I13: =Summary!M24 -> 0 | J13: =Summary!N24+Summary!O24 -> 0 | K13: =Summary!P24 -> 0 | L13: =Summary!Q24+Summary!R24 -> 0 | M13: =Summary!G24+Summary!I24+Summary!S24+Summary!T24+Summary!U24 -> 0 | N13: =SUM(D13:M13) -> 897
B14: 9 | C14: Flying Elephant Studios Pvt.Ltd. | D14: =Summary!F25 -> 0 | E14: =Summary!H25 -> 0 | F14: =Summary!J25 -> 0 | G14: =Summary!K25 -> 0 | H14: =Summary!L25 -> 0 | I14: =Summary!M25 -> 559 | J14: =Summary!N25+Summary!O25 -> 0 | K14: =Summary!P25 -> 0 | L14: =Summary!Q25+Summary!R25 -> 0 | M14: =Summary!G25+Summary!I25+Summary!S25+Summary!T25+Summary!U25 -> 0 | N14: =SUM(D14:M14) -> 559
B15: 10 | C15: Four Lions Films Private Limited | D15: =Summary!F26 -> 0 | E15: =Summary!H26 -> 0 | F15: =Summary!J26 -> 0 | G15: =Summary!K26 -> 0 | H15: =Summary!L26 -> 0 | I15: =Summary!M26 -> 0 | J15: =Summary!N26+Summary!O26 -> 0 | K15: =Summary!P26 -> 207 | L15: =Summary!Q26+Summary!R26 -> 0 | M15: =Summary!G26+Summary!I26+Summary!S26+Summary!T26+Summary!U26 -> 0 | N15: =SUM(D15:M15) -> 207
B16: 11 | C16: Gulliver Motion Pictures LLP | D16: =Summary!F27 -> 0 | E16: =Summary!H27 -> 743 | F16: =Summary!J27 -> 0 | G16: =Summary!K27 -> 0 | H16: =Summary!L27 -> 0 | I16: =Summary!M27 -> 0 | J16: =Summary!N27+Summary!O27 -> 0 | K16: =Summary!P27 -> 0 | L16: =Summary!Q27+Summary!R27 -> 0 | M16: =Summary!G27+Summary!I27+Summary!S27+Summary!T27+Summary!U27 -> 0 | N16: =SUM(D16:M16) -> 743
B17: 12 | C17: High Rise Films Private Limited | D17: =Summary!F28 -> 0 | E17: =Summary!H28 -> 0 | F17: =Summary!J28 -> 0 | G17: =Summary!K28 -> 0 | H17: =Summary!L28 -> 0 | I17: =Summary!M28 -> 370 | J17: =Summary!N28+Summary!O28 -> 1524 | K17: =Summary!P28 -> 0 | L17: =Summary!Q28+Summary!R28 -> 0 | M17: =Summary!G28+Summary!I28+Summary!S28+Summary!T28+Summary!U28 -> 0 | N17: =SUM(D17:M17) -> 1894
B18: 13 | C18: In 10 Media Pvt.Ltd. | D18: =Summary!F29 -> 73 | E18: =Summary!H29 -> 258 | F18: =Summary!J29 -> 788 | G18: =Summary!K29 -> 0 | H18: =Summary!L29 -> 0 | I18: =Summary!M29 -> 0 | J18: =Summary!N29+Summary!O29 -> 0 | K18: =Summary!P29 -> 0 | L18: =Summary!Q29+Summary!R29 -> 0 | M18: =Summary!G29+Summary!I29+Summary!S29+Summary!T29+Summary!U29 -> 0 | N18: =SUM(D18:M18) -> 1119
B19: 14 | C19: Mahesh Pandey Production LLP | D19: =Summary!F30 -> 0 | E19: =Summary!H30 -> 432 | F19: =Summary!J30 -> 0 | G19: =Summary!K30 -> 0 | H19: =Summary!L30 -> 0 | I19: =Summary!M30 -> 0 | J19: =Summary!N30+Summary!O30 -> 0 | K19: =Summary!P30 -> 0 | L19: =Summary!Q30+Summary!R30 -> 0 | M19: =Summary!G30+Summary!I30+Summary!S30+Summary!T30+Summary!U30 -> 0 | N19: =SUM(D19:M19) -> 432
B20: 15 | C20: Maximus Films | D20: =Summary!F31 -> 0 | E20: =Summary!H31 -> 0 | F20: =Summary!J31 -> 0 | G20: =Summary!K31 -> 0 | H20: =Summary!L31 -> 0 | I20: =Summary!M31 -> 0 | J20: =Summary!N31+Summary!O31 -> 0 | K20: =Summary!P31 -> 547 | L20: =Summary!Q31+Summary!R31 -> 0 | M20: =Summary!G31+Summary!I31+Summary!S31+Summary!T31+Summary!U31 -> 0 | N20: =SUM(D20:M20) -> 547
B21: 16 | C21: Planet Marathi | D21: =Summary!F32 -> 0 | E21: =Summary!H32 -> 727 | F21: =Summary!J32 -> 0 | G21: =Summary!K32 -> 0 | H21: =Summary!L32 -> 0 | I21: =Summary!M32 -> 0 | J21: =Summary!N32+Summary!O32 -> 0 | K21: =Summary!P32 -> 0 | L21: =Summary!Q32+Summary!R32 -> 0 | M21: =Summary!G32+Summary!I32+Summary!S32+Summary!T32+Summary!U32 -> 40 | N21: =SUM(D21:M21) -> 767
... B29: 24 | C29: Vijaya Entertainment India | D29: =Summary!F40 -> 0 | E29: =Summary!H40 -> 0 | F29: =Summary!J40 -> 0 | G29: =Summary!K40 -> 35 | H29: =Summary!L40 -> 0 | I29: =Summary!M40 -> 1 | J29: =Summary!N40+Summary!O40 -> 0 | K29: =Summary!P40 -> 474 | L29: =Summary!Q40+Summary!R40 -> 923 | M29: =Summary!G40+Summary!I40+Summary!S40+Summary!T40+Summary!U40 -> 11 | N29: =SUM(D29:M29) -> 1444
B30: 25 | C30: Viniyard Films | D30: =Summary!F41 -> 0 | E30: =Summary!H41 -> 0 | F30: =Summary!J41 -> 0 | G30: 0 | H30: =Summary!L41 -> 0 | I30: =Summary!M41 -> 445 | J30: =Summary!N41+Summary!O41 -> 0 | K30: =Summary!P41 -> 0 | L30: =Summary!Q41+Summary!R41 -> 4911 | M30: =Summary!G41+Summary!I41+Summary!S41+Summary!T41+Summary!U41 -> 0 | N30: =SUM(D30:M30) -> 5356
B31: 26 | C31: White Rivers Media Solutions Private Limited | D31: =Summary!F42 -> 506 | E31: =Summary!H42 -> 0 | F31: =Summary!J42 -> 0 | G31: =Summary!K42 -> 0 | H31: =Summary!L42 -> 0 | I31: =Summary!M42 -> 0 | J31: =Summary!N42+Summary!O42 -> 0 | K31: =Summary!P42 -> 0 | L31: =Summary!Q42+Summary!R42 -> 0 | M31: =Summary!G42+Summary!I42+Summary!S42+Summary!T42+Summary!U42 -> 0 | N31: =SUM(D31:M31) -> 506
B32: 27 | D32: =Summary!F43 -> 0 | E32: =Summary!H43 -> 0 | F32: =Summary!J43 -> 0 | G32: =Summary!K43 -> 0 | H32: =Summary!L43 -> 0 | I32: =Summary!M43 -> 0 | J32: =Summary!N43+Summary!O43 -> 0 | K32: =Summary!P43 -> 0 | L32: =Summary!Q43+Summary!R43 -> 0 | M32: =Summary!G43+Summary!I43+Summary!S43+Summary!T43+Summary!U43 -> 0 | N32: =SUM(D32:M32) -> 0
B33: 28 | D33: =Summary!F44 -> 0 | E33: =Summary!H44 -> 0 | F33: =Summary!J44 -> 0 | G33: =Summary!K44 -> 0 | H33: =Summary!L44 -> 0 | I33: =Summary!M44 -> 0 | J33: =Summary!N44+Summary!O44 -> 0 | K33: =Summary!P44 -> 0 | L33: =Summary!Q44+Summary!R44 -> 0 | M33: =Summary!G44+Summary!I44+Summary!S44+Summary!T44+Summary!U44 -> 0 | N33: =SUM(D33:M33) -> 0
B34: 29 | D34: =Summary!F45 -> 0 | E34: =Summary!H45 -> 0 | F34: =Summary!J45 -> 0 | G34: =Summary!K45 -> 0 | H34: =Summary!L45 -> 0 | I34: =Summary!M45 -> 0 | J34: =Summary!N45+Summary!O45 -> 0 | K34: =Summary!P45 -> 0 | L34: =Summary!Q45+Summary!R45 -> 0 | M34: =Summary!G45+Summary!I45+Summary!S45+Summary!T45+Summary!U45 -> 0 | N34: =SUM(D34:M34) -> 0
B35: 30 | D35: =Summary!F46 -> 0 | E35: =Summary!H46 -> 0 | F35: =Summary!J46 -> 0 | G35: =Summary!K46 -> 0 | H35: =Summary!L46 -> 0 | I35: =Summary!M46 -> 0 | J35: =Summary!N46+Summary!O46 -> 0 | K35: =Summary!P46 -> 0 | L35: =Summary!Q46+Summary!R46 -> 0 | M35: =Summary!G46+Summary!I46+Summary!S46+Summary!T46+Summary!U46 -> 0 | N35: =SUM(D35:M35) -> 0
B36: 31 | D36: =Summary!F47 -> 0 | E36: =Summary!H47 -> 0 | F36: =Summary!J47 -> 0 | G36: =Summary!K47 -> 0 | H36: =Summary!L47 -> 0 | I36: =Summary!M47 -> 0 | J36: =Summary!N47+Summary!O47 -> 0 | K36: =Summary!P47 -> 0 | L36: =Summary!Q47+Summary!R47 -> 0 | M36: =Summary!G47+Summary!I47+Summary!S47+Summary!T47+Summary!U47 -> 0 | N36: =SUM(D36:M36) -> 0
B37: 32 | D37: =Summary!F48 -> 0 | E37: =Summary!H48 -> 0 | F37: =Summary!J48 -> 0 | G37: =Summary!K48 -> 0 | H37: =Summary!L48 -> 0 | I37: =Summary!M48 -> 0 | J37: =Summary!N48+Summary!O48 -> 0 | K37: =Summary!P48 -> 0 | L37: =Summary!Q48+Summary!R48 -> 0 | M37: =Summary!G48+Summary!I48+Summary!S48+Summary!T48+Summary!U48 -> 0 | N37: =SUM(D37:M37) -> 0
B38: 33 | D38: =Summary!F49 -> 0 | E38: =Summary!H49 -> 0 | F38: =Summary!J49 -> 0 | G38: =Summary!K49 -> 0 | H38: =Summary!L49 -> 0 | I38: =Summary!M49 -> 0 | J38: =Summary!N49+Summary!O49 -> 0 | K38: =Summary!P49 -> 0 | L38: =Summary!Q49+Summary!R49 -> 0 | M38: =Summary!G49+Summary!I49+Summary!S49+Summary!T49+Summary!U49 -> 0 | N38: =SUM(D38:M38) -> 0
B39: 34 | D39: =Summary!F50 -> 0 | E39: =Summary!H50 -> 0 | F39: =Summary!J50 -> 0 | G39: =Summary!K50 -> 0 | H39: =Summary!L50 -> 0 | I39: =Summary!M50 -> 0 | J39: =Summary!N50+Summary!O50 -> 0 | K39: =Summary!P50 -> 0 | L39: =Summary!Q50+Summary!R50 -> 0 | M39: =Summary!G50+Summary!I50+Summary!S50+Summary!T50+Summary!U50 -> 0 | N39: =SUM(D39:M39) -> 0
B40: 35 | D40: =Summary!F51 -> 0 | E40: =Summary!H51 -> 0 | F40: =Summary!J51 -> 0 | G40: =Summary!K51 -> 0 | H40: =Summary!L51 -> 0 | I40: =Summary!M51 -> 0 | J40: =Summary!N51+Summary!O51 -> 0 | K40: =Summary!P51 -> 0 | L40: =Summary!Q51+Summary!R51 -> 0 | M40: =Summary!G51+Summary!I51+Summary!S51+Summary!T51+Summary!U51 -> 0 | N40: =SUM(D40:M40) -> 0
B41: 36
B42: 37
C44: Total | D44: =SUM(D6:D43) -> 2163 | E44: =SUM(E6:E43) -> 4921 | F44: =SUM(F6:F43) -> 1665 | G44: =SUM(G6:G43) -> 584 | H44: =SUM(H6:H43) -> 961 | I44: =SUM(I6:I43) -> 1646 | J44: =SUM(J6:J43) -> 1524 | K44: =SUM(K6:K43) -> 5142 | ... N44: =SUM(N6:N43) -> 28395 | O44: 32633
B46: Adani Billing Unit as Per Electricity Bill | N46: 45360
B48: Unit Consmption Details
B49: Sr.no. | C49: Item Description | D49: Location Name | N49: Unit | O49: Losses in %
D50: Hospital LT | E50: Bungalow 1 LT Panel | F50: Office Set LT Panel | G50: Police Station | H50: 8000 Sqft | I50: Restaurant | J50: Parsi | K50: Bungalow 2 LT | L50: Villa | M50: ODU
B51: 1 | C51: Units Billed to Parties | D51: =D44 -> 2163 | E51: =E44 -> 4921 | F51: =F44 -> 1665 | G51: =G44 -> 584 | H51: =H44 -> 961 | I51: =I44 -> 1646 | J51: =J44 -> 1524 | K51: =K44 -> 5142 | ... M51: =M44 -> 355 | N51: =SUM(D51:M51) -> 28395 | P51: DONE
...

Sheet Monthly Adani Bill Deatils
A1: Security Deposite = 14,57,750/-
A2: Month | B2: Billing Unit As per Power Supply Agency | C2: Amount As Per Below Calculation | D2: PF Incentive Amount if Maintained >= 0.995 | E2: PF Received Amount As Per Poer Supply Agency Bill | F2: PF Loss Amount
A3: 43556 | B3: =B27 -> 70560 | C3: =B50 -> 1064447.4 | D3: =(B38+B39+B40+B41+B42+B43+B45+B44)*3.5% -> 30729.965 | E3: =-(B47) -> 21949.975 | F3: =D3-E3 -> 8779.99
A4: 43586 | B4: =C27 -> 93000 | C4: =C50 -> 1372775.2 | D4: =(C38+C39+C40+C41+C42+C43+C45+C44)*3.5% -> 39948.195 | E4: =-(C47) -> 39948.195 | F4: =D4-E4 -> 0
A5: 43617 | B5: =D27 -> 63624 | C5: =D50 -> 971027.29 | D5: =(D38+D39+D40+D41+D42+D43+D45+D44)*3.5% -> 28279.097 | E5: =-(D47) -> 28279.097 | F5: =D5-E5 -> 0
A6: 43647 | B6: =E27 -> 62316 | C6: =E50 -> 955344.18 | D6: =(E38+E39+E40+E41+E42+E43+E45+E44)*3.5% -> 27825.203 | E6: =-(E47) -> 27825.203 | F6: =D6-E6 -> 0
A7: 43678 | B7: =F27 -> 59892 | C7: =F50 -> 929889.67 | D7: =(F36+F37+F38+F39+F40+F41+F43+F44)*3.5% -> 26892.725 | E7: =-(F47) -> 19187.815 | F7: =D7-E7 -> 7704.9096
A8: 43709 | B8: =G27 -> 78252 | C8: =G50 -> 1168956.1 | D8: =(G36+G37+G38+G39+G40+G41+G43+G44)*3.5% -> 33039.943 | E8: =-(G47) -> 14338.734 | F8: =D8-E8 -> 18701.209
A9: 43739 | B9: =H27 -> -3014484 | C9: =H50 -> -36745661 | D9: =(H36+H37+H38+H39+H40+H41+H43+H44)*3.5% -> -988062.08 | E9: =-(H47) -> -753576.61 | F9: =D9-E9 -> -234485.47
A10: 43770 | B10: =I27 -> 0 | C10: =I50 -> 180712.5 | D10: =(I36+I37+I38+I39+I40+I41+I43+I44)*3.5% -> 6869.45 | E10: =-(I47) -> 3812.5 | F10: =D10-E10 -> 3056.95
A11: 43800 | B11: =J27 -> 0 | C11: =J50 -> 180712.5 | D11: =(J36+J37+J38+J39+J40+J41+J43+J44)*3.5% -> 6870.5 | E11: =-(J47) -> 3812.5 | F11: =D11-E11 -> 3058
A12: 43831 | B12: =K27 -> 0 | C12: =K50 -> 180712.5 | D12: =(K37+K38+K39+K40+K41+K42+K44+K45)*3.5% -> 6871.585 | E12: =-(K47) -> 3812.5 | F12: =D12-E12 -> 3059.085
A13: 43862 | B13: =L27 -> 0 | C13: =L50 -> 180712.5 | D13: =(L38+L39+L40+L41+L42+L43+L45+L44)*3.5% -> 5337.5 | E13: =-(L47) -> 3812.5 | F13: =D13-E13 -> 1525
A14: 43891 | B14: =M27 -> 0 | C14: =M50 -> 180712.5 | D14: =(M38+M39+M40+M41+M42+M43+M45+M44)*3.5% -> 5337.5 | E14: =-(M47) -> 3812.5 | F14: =D14-E14 -> 1525
A16: Readings | B16: 43556 | C16: 43586 | D16: 43617 | E16: 43647 | F16: 43678 | G16: 43709 | H16: 43739 | I16: 43770 | J16: 43800 | K16: 43831 | L16: 43862 | M16: 43891
A17: Starting | B17: 2155.7 | C17: =B18 -> 2214.5 | D17: =C18 -> 2292 | E17: =D18 -> 2345.02 | F17: =E18 -> 2396.95 | G17: =F18 -> 2446.86 | H17: =G18 -> 2512.07 | I17: =H18 -> 0 | J17: =I18 -> 0 | ... M17: =L18 -> 0
A18: Closing | B18: 2214.5 | C18: 2292 | D18: 2345.02 | E18: 2396.95 | F18: 2446.86 | G18: 2512.07
A19: MF Value | B19: 1200 | C19: 1200 | D19: 1200 | E19: 1200 | F19: 1200 | G19: 1200 | H19: 1200 | I19: 1200 | J19: 1200 | K19: 1200 | L19: 1200 | M19: 1200
A20: Consumption | B20: =(B18-B17)*B19 -> 70560 | C20: =(C18-C17)*C19 -> 93000 | D20: =(D18-D17)*D19 -> 63624 | E20: =(E18-E17)*E19 -> 62316 | F20: =(F18-F17)*F19 -> 59892 | G20: =(G18-G17)*G19 -> 78252 | H20: =(H18-H17)*H19 -> -3014484 | I20: =(I18-I17)*I19 -> 0 | ... M20: =(M18-M17)*M19 -> 0
A22: Ellora Electricity Bill Details - Consumer No - 152283599
A23: Month | B23: 43556 | C23: 43586 | D23: 43617 | E23: 43647 | F23: 43678 | G23: 43709 | H23: 43739 | I23: 43770 | J23: 43800 | K23: 43831 | L23: 43862 | M23: 43891
A24: Tariff Cat | B24: HT II | C24: HT II | D24: HT II | E24: HT II | F24: HT II | G24: HT II | H24: HT II | I24: HT II | J24: HT II | K24: HT II | L24: HT II | M24: HT II
A25: Meter no. | B25: H952738 | C25: H952738 | D25: H952738 | E25: H952738 | F25: H952738 | G25: H952738 | H25: H952738 | I25: H952738 | J25: H952738 | K25: H952738 | L25: H952738 | M25: H952738
A26: Bill No | B26: 100398625474 | C26: 10058642815 | D26: 10003133890 | E26: 101294024800 | F26: 101294056772 | G26: 101294084308
A27: Meter Units | B27: =B20 -> 70560 | C27: =C20 -> 93000 | D27: =D20 -> 63624 | E27: =E20 -> 62316 | F27: =F20 -> 59892 | G27: =G20 -> 78252 | H27: =H20 -> -3014484 | I27: =I20 -> 0 | ... M27: =M20 -> 0
A28: 9:00 Hrs - 12:00 Hrs | B28: 12072 | C28: 15792 | D28: =28524-C28 -> 12732 | E28: 12480 | F28: 11388 | G28: 14220
A29: 18:00 Hrs - 22:00 Hrs | B29: 17220 | C29: 21264 | D29: =35280-C29 -> 14016 | E29: 14472 | F29: 13452 | G29: 17712
A30: 22:00 Hrs - 6:00 Hrs | B30: 9180 | C30: 12612 | D30: =18384-C30 -> 5772 | E30: 5976 | F30: 8064 | G30: 10452
A31: Unit Use Between (6:00 Hrs - 9:00 Hrs and 12:00 Hrs - 18:00 Hrs (No Electricity Extra Charges) | B31: =B27-(B28+B29+B30) -> 32088 | C31: =C27-(C28+C29+C30) -> 43332 | D31: =D27-(D28+D29+D30) -> 31104 | E31: =E27-(E28+E29+E30) -> 29388 | F31: =F27-(F28+F29+F30) -> 26988 | G31: =G27-(G28+G29+G30) -> 35868 | H31: =H27-(H28+H29+H30) -> -3014484 | I31: =I27-(I28+I29+I30) -> 0 | ... M31: =M27-(M28+M29+M30) -> 0
A32: Sanctioned demand | B32: 1000 | C32: 1000 | D32: 1000 | E32: 1000 | F32: 1000 | G32: 1000 | H32: 1000 | I32: 1000 | J32: 1000 | K32: 1000 | L32: 1000 | M32: 1000
A33: Maximum demand | B33: 484.4 | C33: 613.2 | D33: 400 | E33: 364.8 | F33: 404.4 | G33: 494.4
A34: PF Value | B34: 0.991 | C34: 0.995 | D34: 0.995 | E34: 0.995 | F34: 0.986 | G34: 0.977
A35: Billing amount As Per Power Supply Agency | B35: =B63 -> 1064447.4 | C35: =C63 -> 1372775.2 | D35: =D63 -> 971027.29 | E35: =E63 -> 955344.18 | F35: =F63 -> 929889.67 | G35: =G63 -> 1168956.1 | H35: =H63 -> -36745661 | I35: =I63 -> 180712.5 | ... M35: =M63 -> 180712.5
A37: Calculation | B37: 43556 | C37: 43586 | D37: 43617 | E37: 43647 | F37: 43678 | G37: 43709 | H37: 43739 | I37: 43770 | J37: 43800 | K37: 43831 | L37: 43862 | M37: 43891 | P37: =524.4*275 -> 144210 | Q37: =410.4*275 -> 112860
A38: Demand/Fixed Charge | B38: =IF(B33>500,(B33*305),(500*305)) -> 152500 | C38: =(IF(C33>500,(C33*305),(500*305))) -> 187026 | D38: =(IF(D33>500,(D33*305),(500*305))) -> 152500 | E38: =(IF(E33>500,(E33*305),(500*305))) -> 152500 | F38: =(IF(F33>500,(F33*305),(500*305))) -> 152500 | G38: =(IF(G33>500,(G33*305),(500*305))) -> 152500 | H38: =(IF(H33>500,(H33*305),(500*305))) -> 152500 | I38: =(IF(I33>500,(I33*305),(500*305))) -> 152500 | J38: =(IF(J33>500,(J33*305),(500*305))) -> 152500 | ... M38: =(IF(M33>500,(M33*305),(500*305))) -> 152500
A39: Whelling Charges | B39: =B27*0.72 -> 50803.2 | C39: =C27*0.72 -> 66960 | D39: =D27*0.72 -> 45809.28 | E39: =E27*0.72 -> 44867.52 | F39: =F27*0.72 -> 43122.24 | G39: =G27*0.72 -> 56341.44 | H39: =H27*0.72 -> -2170428.5 | I39: =I27*0.72 -> 0 | ... M39: =M27*0.72 -> 0
A40: Regulatory Asset Charge | B40: =B27*0.76 -> 53625.6 | C40: =C27*0.76 -> 70680 | D40: =D27*0.76 -> 48354.24 | E40: =E27*0.76 -> 47360.16 | F40: =F27*0.76 -> 45517.92 | G40: =G27*0.76 -> 59471.52 | H40: =H27*0.76 -> -2291007.8 | I40: =I27*0.76 -> 0 | ... M40: =M27*0.76 -> 0
A41: Energy Charges | B41: =B27*7.95 -> 560952 | C41: =C27*7.95 -> 739350 | D41: =D27*7.95 -> 505810.8 | E41: =E27*7.95 -> 495412.2 | F41: =F27*7.95 -> 476141.4 | G41: =G27*7.95 -> 622103.4 | H41: =H27*7.95 -> -23965148 | I41: =I27*7.95 -> 0 | ... M41: =M27*7.95 -> 0
A42: 9:00 Hrs - 12: Hrs | B42: =B28*0.5 -> 6036 | C42: =C28*0.5 -> 7896 | D42: =D28*0.5 -> 6366 | E42: =E28*0.5 -> 6240 | F42: =F28*0.5 -> 5694 | G42: =G28*0.5 -> 7110 | H42: =H28*0.5 -> 0 | I42: =I28*0.5 -> 0 | ... M42: =M28*0.5 -> 0
A43: 18:00 Hrs - 22:00 Hrs | B43: =B29*1 -> 17220 | C43: =C29*1 -> 21264 | D43: =D29*1 -> 14016 | E43: =E29*1 -> 14472 | F43: =F29*1 -> 13452 | G43: =G29*1 -> 17712 | H43: =H29*1 -> 0 | I43: =I29*1 -> 0 | ... M43: =M29*1 -> 0
...

Sheet Monthly Fire Meter
A1: Security Deposite = 10,630/-
A2: Month | B2: Billing Unit As per Power Supply Agency | C2: Amount As Per Below Calculation | D2: PF Incentive Amount if Maintained >= 0.995 | E2: PF Received Amount As Per Poer Supply Agency Bill | F2: PF Loss Amount
A3: 43556 | B3: =B27 -> 25.9 | C3: =B50 -> 6511.0466 | D3: =(B38+B39+B40+B41+B42+B43+B45+B44)*3.5% -> 136.6827 | E3: =-(B47) -> -1776.88 | F3: =D3-E3 -> 1913.5627
A4: 43586 | B4: =C27 -> 100.1 | C4: =C50 -> 20500.974 | D4: =(C38+C39+C40+C41+C42+C43+C45+C44)*3.5% -> 460.63437 | E4: =-(C47) -> -4542.112 | F4: =D4-E4 -> 5002.7464
A5: 43617 | B5: =D27 -> 129.6 | C5: =D50 -> 16330.992 | D5: =(D38+D39+D40+D41+D42+D43+D45+D44)*3.5% -> 471.10798 | E5: =-(D47) -> 0 | F5: =D5-E5 -> 471.10798
A6: 43647 | B6: =E27 -> 22.4 | C6: =E50 -> 15511.54 | D6: =(E38+E39+E40+E41+E42+E43+E45+E44)*3.5% -> 434.11354 | E6: =-(E47) -> -495.99 | F6: =D6-E6 -> 930.10354
A7: 43678 | B7: =F27 -> 2 | C7: =F50 -> 16008.37 | D7: =(F36+F37+F38+F39+F40+F41+F43+F44)*3.5% -> 1956.3733 | E7: =-(F47) -> -1221.961 | F7: =D7-E7 -> 3178.3343
A8: 43709 | B8: =G27 -> 56.4 | C8: =G50 -> 15379.977 | D8: =(G36+G37+G38+G39+G40+G41+G43+G44)*3.5% -> 1974.7548 | E8: =-(G47) -> 63.73767 | F8: =D8-E8 -> 1911.0171
A9: 43739 | B9: =H27 -> -220.4 | C9: =H50 -> 11819.859 | D9: =(H36+H37+H38+H39+H40+H41+H43+H44)*3.5% -> 1886.9733 | E9: =-(H47) -> 250.9469 | F9: =D9-E9 -> 1636.0264
A10: 43770 | B10: =I27 -> 0 | C10: =I50 -> 14457 | D10: =(I36+I37+I38+I39+I40+I41+I43+I44)*3.5% -> 1958.95 | E10: =-(I47) -> 305 | F10: =D10-E10 -> 1653.95
A11: 43800 | B11: =J27 -> 0 | C11: =J50 -> 14457 | D11: =(J36+J37+J38+J39+J40+J41+J43+J44)*3.5% -> 1960 | E11: =-(J47) -> 305 | F11: =D11-E11 -> 1655
A12: 43831 | B12: =K27 -> 0 | C12: =K50 -> 14457 | D12: =(K37+K38+K39+K40+K41+K42+K44+K45)*3.5% -> 1961.085 | E12: =-(K47) -> 305 | F12: =D12-E12 -> 1656.085
A13: 43862 | B13: =L27 -> 0 | C13: =L50 -> 14457 | D13: =(L38+L39+L40+L41+L42+L43+L45+L44)*3.5% -> 427 | E13: =-(L47) -> 305 | F13: =D13-E13 -> 122
A14: 43891 | B14: =M27 -> 0 | C14: =M50 -> 14457 | D14: =(M38+M39+M40+M41+M42+M43+M45+M44)*3.5% -> 427 | E14: =-(M47) -> 305 | F14: =D14-E14 -> 122
A16: Readings | B16: 43556 | C16: 43586 | D16: 43617 | E16: 43647 | F16: 43678 | G16: 43709 | H16: 43739 | I16: 43770 | J16: 43800 | K16: 43831 | L16: 43862 | M16: 43891
A17: Starting | B17: 530 | C17: 0 | D17: =C18 -> 0.25 | E17: =D18 -> 3.49 | F17: =E18 -> 4.05 | G17: =F18 -> 4.1 | H17: =G18 -> 5.51 | I17: =H18 -> 0 | J17: =I18 -> 0 | K17: =J18 -> 0 | ... M17: =L18 -> 0
A18: Closing | B18: 555.9 | C18: 0.25 | D18: 3.49 | E18: 4.05 | F18: 4.1 | G18: 5.51
A19: MF Value | B19: 1 | C19: 40 | D19: 40 | E19: 40 | F19: 40 | G19: 40 | H19: 40 | I19: 40 | J19: 40 | K19: 40 | L19: 40 | M19: 40
A20: Consumption | B20: =(B18-B17)*B19 -> 25.9 | C20: =((C18-C17)*C19)+(646-555.9) -> 100.1 | D20: =(D18-D17)*D19 -> 129.6 | E20: =(E18-E17)*E19 -> 22.4 | F20: =(F18-F17)*F19 -> 2 | G20: =(G18-G17)*G19 -> 56.4 | H20: =(H18-H17)*H19 -> -220.4 | I20: =(I18-I17)*I19 -> 0 | J20: =(J18-J17)*J19 -> 0 | K20: =(K18-K17)*K19 -> 0 | ... M20: =(M18-M17)*M19 -> 0
A22: Ellora Electricity Bill Details - Consumer No - 152283599
A23: Month | B23: 43556 | C23: 43586 | D23: 43617 | E23: 43647 | F23: 43678 | G23: 43709 | H23: 43739 | I23: 43770 | J23: 43800 | K23: 43831 | L23: 43862 | M23: 43891
A24: Tariff Cat | B24: LT II (B) | C24: LT II (B) | D24: LT II (B) | E24: LT II (B) | F24: LT II (B) | G24: LT II (B) | H24: LT II (B) | I24: LT II (B) | J24: LT II (B) | K24: LT II (B) | L24: LT II (B) | M24: LT II (B)
A25: Meter no. | B25: 9078662 | C25: 9078662 + L1009720 | D25: L1009720 | E25: L1009720 | F25: L1009720 | G25: L1009720 | H25: L1009720 | I25: L1009720 | J25: L1009720 | K25: L1009720 | L25: L1009720 | M25: L1009720
A26: Bill No | B26: 100668217247 | C26: 100936340917 | D26: 101773066476 | E26: 100308838039 | F26: 100877729853 | G26: 101683343757
A27: Meter Units | B27: =B20 -> 25.9 | C27: =C20 -> 100.1 | D27: =D20 -> 129.6 | E27: =E20 -> 22.4 | F27: =F20 -> 2 | G27: =G20 -> 56.4 | H27: =H20 -> -220.4 | I27: =I20 -> 0 | ... M27: =M20 -> 0
A28: 9:00 Hrs - 12:00 Hrs | B28: 3 | C28: 3 | D28: 18 | E28: 0 | F28: 0 | G28: 0
A29: 18:00 Hrs - 22:00 Hrs | B29: 2 | C29: 20 | D29: 27 | E29: 0 | F29: 0 | G29: 16
A30: 22:00 Hrs - 6:00 Hrs | B30: 6 | C30: 58 | D30: 62 | E30: 22 | F30: 0 | G30: 29
A31: Unit Use Between (6:00 Hrs - 9:00 Hrs and 12:00 Hrs - 18:00 Hrs (No Electricity Extra Charges) | B31: =B27-(B28+B29+B30) -> 14.9 | C31: =C27-(C28+C29+C30) -> 19.1 | D31: =D27-(D28+D29+D30) -> 22.6 | E31: =E27-(E28+E29+E30) -> 0.4 | F31: =F27-(F28+F29+F30) -> 2 | G31: =G27-(G28+G29+G30) -> 11.4 | H31: =H27-(H28+H29+H30) -> -220.4 | I31: =I27-(I28+I29+I30) -> 0 | ... M31: =M27-(M28+M29+M30) -> 0
A32: Sanctioned demand | B32: 30 | C32: 100 | D32: 100 | E32: 100 | F32: 100 | G32: 100 | H32: 100 | I32: 100 | J32: 100 | K32: 100 | L32: 100 | M32: 100
A33: Maximum demand | C33: 14.98 | D33: 5.2 | E33: 4.24 | F33: 1.84 | G33: 5.5
A34: PF Value | B34: 0.2 | C34: 0.507 | D34: 0.916 | E34: 0.826 | F34: 0.707 | G34: 0.962
A35: Billing amount As Per Power Supply Agency | B35: =B63 -> 6511.0466 | C35: =C63 -> 20500.974 | D35: =D63 -> 16330.992 | E35: =E63 -> 15511.54 | F35: =F63 -> 16008.37 | G35: =G63 -> 15379.977 | H35: =H63 -> 11819.859 | I35: =I63 -> 14457 | ... M35: =M63 -> 14457
A37: Calculation | B37: 43556 | C37: 43586 | D37: 43617 | E37: 43647 | F37: 43678 | G37: 43709 | H37: 43739 | I37: 43770 | J37: 43800 | K37: 43831 | L37: 43862 | M37: 43891 | P37: =524.4*275 -> 144210 | Q37: =410.4*275 -> 112860
A38: Demand/Fixed Charge | B38: =IF(B33>12,(B33*305),(12*305)) -> 3660 | C38: =(IF(C33>40,(C33*305),(40*305))) -> 12200 | D38: =(IF(D33>40,(D33*305),(40*305))) -> 12200 | E38: =(IF(E33>40,(E33*305),(40*305))) -> 12200 | F38: =(IF(F33>40,(F33*305),(40*305))) -> 12200 | G38: =(IF(G33>40,(G33*305),(40*305))) -> 12200 | H38: =(IF(H33>40,(H33*305),(40*305))) -> 12200 | I38: =(IF(I33>40,(I33*305),(40*305))) -> 12200 | J38: =(IF(J33>40,(J33*305),(40*305))) -> 12200 | ... M38: =(IF(M33>40,(M33*305),(40*305))) -> 12200
A39: Whelling Charges | B39: =26*1.57 -> 40.82 | C39: =C27*1.57 -> 157.157 | D39: =D27*1.57 -> 203.472 | E39: =E27*1.57 -> 35.168 | F39: =F27*1.57 -> 3.14 | G39: =G27*1.57 -> 88.548 | H39: =H27*1.57 -> -346.028 | I39: =I27*1.57 -> 0 | J39: =J27*1.57 -> 0 | ... M39: =M27*1.57 -> 0
A40: Regulatory Asset Charge | B40: =26*0.45 -> 11.7 | C40: =C27*0.47 -> 47.047 | D40: =D27*0.47 -> 60.912 | E40: =E27*0.47 -> 10.528 | F40: =F27*0.47 -> 0.94 | G40: =G27*0.47 -> 26.508 | H40: =H27*0.47 -> -103.588 | I40: =I27*0.47 -> 0 | J40: =J27*0.47 -> 0 | ... M40: =M27*0.47 -> 0
A41: Energy Charges | B41: =26*6.85 -> 178.1 | C41: =C27*7.15 -> 715.715 | D41: =D27*7.15 -> 926.64 | E41: =E27*7.15 -> 160.16 | F41: =F27*7.15 -> 14.3 | G41: =G27*7.15 -> 403.26 | H41: =H27*7.15 -> -1575.86 | I41: =I27*7.15 -> 0 | J41: =J27*7.15 -> 0 | ... M41: =M27*7.15 -> 0
A42: 9:00 Hrs - 12: Hrs | B42: =B28*0.5 -> 1.5 | C42: =C28*0.5 -> 1.5 | D42: =D28*0.5 -> 9 | E42: =E28*0.5 -> 0 | F42: =F28*0.5 -> 0 | G42: =G28*0.5 -> 0 | H42: =H28*0.5 -> 0 | I42: =I28*0.5 -> 0 | ... M42: =M28*0.5 -> 0
A43: 18:00 Hrs - 22:00 Hrs | B43: =B29*1 -> 2 | C43: =C29*1 -> 20 | D43: =D29*1 -> 27 | E43: =E29*1 -> 0 | F43: =F29*1 -> 0 | G43: =G29*1 -> 16 | H43: =H29*1 -> 0 | I43: =I29*1 -> 0 | ... M43: =M29*1 -> 0
...

Sheet Monthly Unit Losses
B2: Monthly Unit Losses | L2: Main LT Panel Unit Looses | S2: Capacitor Bank Operational Unit Looses | W2: Location LT Panels Energy Meter +- 1% unit Tolerance and Cable Looses
B3: Month | C3: Transformer Unit Looses | E3: Capacitor Bank Operational Unit Looses | G3: Main LT Panel Energy +- 1% Unit Tolerance Looses | I3: Location LT Panels Energy Meter +- 1% unit Tolerance and Cable Looses | K3: Total Looses | L3: Month | M3: Ellora Main LT Panel Meter Units | P3: Capacitor Bank Operational Unit Losses | Q3: Main LT Panel Energy +- 1% Unit Tolerance Looses | S3: Month | T3: Fixed Capacitor Bank (50 KVA)Operational Unit Losses | U3: Variable Capacitor Bank Operational Unit Losses | V3: Capacitor Bank Operatinal Unit Losses | W3: Month | X3: Sum Of Main LT Panel O/P Meter Units | Y3: Sum Of All Location LT Panel I/P Meter Units | Z3: Unit Looses
C4: Units | D4: in % | E4: Unit | F4: in % | G4: Units | H4: in % | I4: Units | J4: in % | M4: Incomer Meter Units | N4: All O/P Meter Units | O4: Unit Looses | Q4: Units | R4: in % | Z4: Units | AA4: in %
B5: 43556 | C5: =O22 -> 3430 | D5: =W22/100 -> 0.016035875 | E5: =V5 -> 64.0224 | F5: =E5/M5 -> 0.00095370773 | G5: =Q5 -> 340.9776 | H5: =R5 -> 0.0050793624 | I5: =Z5 -> 1187 | J5: =AA5 -> 0.017789434 | K5: =C5+E5+G5+I5 -> 5022 | L5: 43556 | M5: =N22 -> 67130 | N5: 66725 | O5: =(M5-N5) -> 405 | P5: =V5 -> 64.0224 | Q5: =O5-P5 -> 340.9776 | R5: =Q5/M5 -> 0.0050793624 | S5: 43556 | T5: =V38 -> 16.2 | U5: =U38 -> 47.8224 | V5: =U5+T5 -> 64.0224 | W5: 43556 | X5: 66725 | Y5: 65538 | Z5: =X5-Y5 -> 1187 | AA5: =Z5/X5 -> 0.017789434
B6: 43586 | C6: =O23 -> 4640 | D6: =W23/100 -> 0.025654983 | E6: =V6 -> 66.15648 | F6: =E6/M6 -> 0.00074871526 | G6: =Q6 -> 583.84352 | H6: =R6 -> 0.0066075545 | I6: =Z6 -> 1637 | J6: =AA6 -> 0.018663778 | K6: =C6+E6+G6+I6 -> 6927 | L6: 43586 | M6: =N23 -> 88360 | N6: 87710 | O6: =(M6-N6) -> 650 | P6: =V6 -> 66.15648 | Q6: =O6-P6 -> 583.84352 | R6: =Q6/M6 -> 0.0066075545 | S6: 43586 | T6: =V39 -> 16.74 | U6: =U39 -> 49.41648 | V6: =T6+U6 -> 66.15648 | W6: 43586 | X6: 87710 | Y6: 86073 | Z6: =X6-Y6 -> 1637 | AA6: =Z6/X6 -> 0.018663778
B7: 43617 | C7: =O24 -> 3404 | D7: =W24/100 -> 0.010916601 | E7: =V7 -> 64.0224 | F7: =E7/M7 -> 0.0010631418 | G7: =Q7 -> 653.9776 | H7: =R7 -> 0.010859807 | I7: =Z7 -> 1418 | J7: =AA7 -> 0.023831132 | K7: =C7+E7+G7+I7 -> 5540 | L7: 43617 | M7: =N24 -> 60220 | N7: 59502 | O7: =(M7-N7) -> 718 | P7: =V7 -> 64.0224 | Q7: =O7-P7 -> 653.9776 | R7: =Q7/M7 -> 0.010859807 | S7: 43617 | T7: =V40 -> 16.2 | U7: =U40 -> 47.8224 | V7: =T7+U7 -> 64.0224 | W7: 43617 | X7: 59502 | Y7: 58084 | Z7: =X7-Y7 -> 1418 | AA7: =Z7/X7 -> 0.023831132
B8: 43647 | C8: =O25 -> 3186 | D8: =W25/100 -> 0.0090798171 | E8: =V8 -> 66.15648 | F8: =E8/M8 -> 0.0011188311 | G8: =Q8 -> 907.84352 | H8: =R8 -> 0.015353349 | I8: =Z8 -> 1365 | J8: =AA8 -> 0.023471353 | K8: =C8+E8+G8+I8 -> 5525 | L8: 43647 | M8: =N25 -> 59130 | N8: 58156 | O8: =(M8-N8) -> 974 | P8: =V8 -> 66.15648 | Q8: =O8-P8 -> 907.84352 | R8: =Q8/M8 -> 0.015353349 | S8: 43647 | T8: =V41 -> 16.74 | U8: =U41 -> 49.41648 | V8: =T8+U8 -> 66.15648 | W8: 43647 | X8: 58156 | Y8: 56791 | Z8: =X8-Y8 -> 1365 | AA8: =Z8/X8 -> 0.023471353
B9: 43678 | C9: =O26 -> 3732 | D9: =W26/100 -> 0.011158087 | E9: =V9 -> 66.15648 | F9: =E9/M9 -> 0.001178 | G9: =Q9 -> 2008.8435 | H9: =R9 -> 0.035770006 | I9: =Z9 -> -114 | J9: =AA9 -> -0.0021077933 | K9: =C9+E9+G9+I9 -> 5693 | L9: 43678 | M9: =N26 -> 56160 | N9: 54085 | O9: =(M9-N9) -> 2075 | P9: =V9 -> 66.15648 | Q9: =O9-P9 -> 2008.8435 | R9: =Q9/M9 -> 0.035770006 | S9: 43678 | T9: =V42 -> 16.74 | U9: =U42 -> 49.41648 | V9: =T9+U9 -> 66.15648 | W9: 43678 | X9: 54085 | Y9: 54199 | Z9: =X9-Y9 -> -114 | AA9: =Z9/X9 -> -0.0021077933
B10: 44013 | C10: =O27 -> 2892 | D10: =W27/100 -> 0.0054759641 | E10: =V10 -> 66.15648 | F10: =E10/M10 -> 0.0022602146 | G10: =Q10 -> 43.84352 | H10: =R10 -> 0.0014978996 | I10: =Z10 -> 2527 | J10: =AA10 -> 0.086334131 | K10: =C10+E10+G10+I10 -> 5529 | L10: 44013 | M10: =N27 -> 29270 | N10: 29160 | O10: =(M10-N10) -> 110 | P10: =V10 -> 66.15648 | Q10: =O10-P10 -> 43.84352 | R10: =Q10/M10 -> 0.0014978996 | S10: 44013 | T10: =V43 -> 16.74 | U10: =U43 -> 49.41648 | V10: =T10+U10 -> 66.15648 | W10: 44013 | X10: 29270 | Y10: 26743 | Z10: =X10-Y10 -> 2527 | AA10: =Z10/X10 -> 0.086334131
B11: 44045 | C11: =O28 -> 4158 | D11: =W28/100 -> 0.011581422 | E11: =V11 -> 66.15648 | F11: =E11/M11 -> 0.0011361236 | G11: =Q11 -> 283.84352 | H11: =R11 -> 0.0048745238 | I11: =Z11 -> 3211 | J11: =AA11 -> 0.056331357 | K11: =C11+E11+G11+I11 -> 7719 | L11: 44045 | M11: =N28 -> 58230 | N11: 57880 | O11: =(M11-N11) -> 350 | P11: =V11 -> 66.15648 | Q11: =O11-P11 -> 283.84352 | R11: =Q11/M11 -> 0.0048745238 | S11: 44045 | T11: =V44 -> 16.74 | U11: =U44 -> 49.41648 | V11: =T11+U11 -> 66.15648 | W11: 44045 | X11: 57002 | Y11: 53791 | Z11: =X11-Y11 -> 3211 | AA11: =Z11/X11 -> 0.056331357
B12: 44077 | C12: =O29 -> 4428 | D12: =W29/100 -> 0.01027143 | E12: =V12 -> 64.0224 | F12: =E12/M12 -> 0.00092866841 | G12: =Q12 -> 315.9776 | H12: =R12 -> 0.004583371 | I12: =Z12 -> 1233 | J12: =AA12 -> 0.0183403 | K12: =C12+E12+G12+I12 -> 6041 | L12: 44077 | M12: =N29 -> 68940 | N12: 68560 | O12: =(M12-N12) -> 380 | P12: =V12 -> 64.0224 | Q12: =O12-P12 -> 315.9776 | R12: =Q12/M12 -> 0.004583371 | S12: 44077 | T12: =V45 -> 16.2 | U12: =U45 -> 47.8224 | V12: =T12+U12 -> 64.0224 | W12: 44077 | X12: 67229 | Y12: 65996 | Z12: =X12-Y12 -> 1233 | AA12: =Z12/X12 -> 0.0183403
B13: 44109 | C13: =O30 -> 3226 | D13: =W30/100 -> 0.005122342 | E13: =V13 -> 66.15648 | F13: =E13/M13 -> 0.0014665591 | G13: =Q13 -> -346.15648 | H13: =R13 -> -0.0076736085 | I13: =Z13 -> 550 | J13: =AA13 -> 0.012117206 | K13: =C13+E13+G13+I13 -> 3496 | L13: 44109 | M13: 45110 | N13: 45390 | O13: =(M13-N13) -> -280 | P13: =V13 -> 66.15648 | Q13: =O13-P13 -> -346.15648 | R13: =Q13/M13 -> -0.0076736085 | S13: 44109 | T13: =V46 -> 16.74 | U13: =U46 -> 49.41648 | V13: =T13+U13 -> 66.15648 | W13: 44109 | X13: 45390 | Y13: 44840 | Z13: =X13-Y13 -> 550 | AA13: =Z13/X13 -> 0.012117206
B14: 44141 | C14: =O31 -> 3350 | D14: =W31/100 -> 0.014125058 | E14: =V14 -> 64.0224 | F14: =E14/M14 -> 0.00152398 | G14: =Q14 -> 598.9776 | H14: =R14 -> 0.014257977 | I14: =Z14 -> 663 | J14: =AA14 -> 0.015781957 | K14: =C14+E14+G14+I14 -> 4676 | L14: 44141 | M14: =N31 -> 42010 | N14: 41347 | O14: =(M14-N14) -> 663 | P14: =V14 -> 64.0224 | Q14: =O14-P14 -> 598.9776 | R14: =Q14/M14 -> 0.014257977 | S14: 44141 | T14: =V47 -> 16.2 | U14: =U47 -> 47.8224 | V14: =T14+U14 -> 64.0224 | W14: 44141 | X14: 42010 | Y14: 41347 | Z14: =X14-Y14 -> 663 | AA14: =Z14/X14 -> 0.015781957
L19: Transformer Monthly Losses Details
L20: Month | M20: Reliance/Adani Billing Units | N20: Ellora Main LT Panel Incomer Meter Units | O20: Unit Losses | P20: Transformer Losses | U20: Maximum Demand (KVA) | V20: % of Load Utilized Compare With Transformer Full Load | W20: Load Losses in %
P21: Monthly Iron Losses(fixed 1.5 unit(KWH) consumed per hour | Q21: Cu losses( I²R, Depend on load) | R21: Power Factor | S21: Iron Losses in % | T21: cu Losses in %
L22: 43556 | M22: 70560 | N22: 67130 | O22: =M22-N22 -> 3430 | P22: =1.5*24*30 -> 1080 | Q22: =O22-P22 -> 2350 | R22: 0.991 | S22: =(P22/M22)*100 -> 1.5306122 | T22: =(Q22/M22)*100 -> 3.3304989 | U22: 484.8 | V22: =(U22/1250) -> 0.38784 | W22: =+((3*37.87*V22*37.87*V22*0.882*1.5)+(3*1667*V22*1667*V22*0.596)/1000)/1000 -> 1.6035875
L23: 43586 | M23: 93000 | N23: 88360 | O23: =M23-N23 -> 4640 | P23: =1.5*24*31 -> 1116 | Q23: =O23-P23 -> 3524 | R23: 0.995 | S23: =(P23/M23)*100 -> 1.2 | T23: =(Q23/M23)*100 -> 3.7892473 | U23: 613.2 | V23: =(U23/1250) -> 0.49056 | W23: =+((3*37.87*V23*37.87*V23*0.882*1.5)+(3*1667*V23*1667*V23*0.596)/1000)/1000 -> 2.5654983
L24: 43617 | M24: 63624 | N24: 60220 | O24: =M24-N24 -> 3404 | P24: =1.5*24*30 -> 1080 | Q24: =O24-P24 -> 2324 | R24: 0.996 | S24: =(P24/M24)*100 -> 1.6974727 | T24: =(Q24/M24)*100 -> 3.6527097 | U24: 400 | V24: =(U24/1250) -> 0.32 | W24: =+((3*37.87*V24*37.87*V24*0.882*1.5)+(3*1667*V24*1667*V24*0.596)/1000)/1000 -> 1.0916601
L25: 43647 | M25: 62316 | N25: 59130 | O25: =M25-N25 -> 3186 | P25: =1.5*24*31 -> 1116 | Q25: =O25-P25 -> 2070 | R25: 0.995 | S25: =(P25/M25)*100 -> 1.7908723 | T25: =(Q25/M25)*100 -> 3.3217793 | U25: 364.8 | V25: =(U25/1250) -> 0.29184 | W25: =+((3*37.87*V25*37.87*V25*0.882*1.5)+(3*1667*V25*1667*V25*0.596)/1000)/1000 -> 0.90798171
L26: 43678 | M26: 59892 | N26: 56160 | O26: =M26-N26 -> 3732 | P26: =1.5*24*31 -> 1116 | Q26: =O26-P26 -> 2616 | R26: 0.986 | S26: =(P26/M26)*100 -> 1.863354 | T26: =(Q26/M26)*100 -> 4.3678622 | U26: 404.4 | V26: =(U26/1250) -> 0.32352 | W26: =+((3*37.87*V26*37.87*V26*0.882*1.5)+(3*1667*V26*1667*V26*0.596)/1000)/1000 -> 1.1158087
L27: 44013 | M27: 32162 | N27: 29270 | O27: =M27-N27 -> 2892 | P27: =1.5*24*30 -> 1080 | Q27: =O27-P27 -> 1812 | R27: 0.977 | S27: =(P27/M27)*100 -> 3.3580001 | T27: =(Q27/M27)*100 -> 5.633978 | U27: 283.3 | V27: =(U27/1250) -> 0.22664 | W27: =+((3*37.87*V27*37.87*V27*0.882*1.5)+(3*1667*V27*1667*V27*0.596)/1000)/1000 -> 0.54759641
L28: 44045 | M28: 62388 | N28: 58230 | O28: =M28-N28 -> 4158 | P28: =1.5*24*31 -> 1116 | Q28: =O28-P28 -> 3042 | R28: 0.996 | S28: =(P28/M28)*100 -> 1.7888055 | T28: =(Q28/M28)*100 -> 4.8759377 | U28: 412 | V28: =(U28/1250) -> 0.3296 | W28: =+((3*37.87*V28*37.87*V28*0.882*1.5)+(3*1667*V28*1667*V28*0.596)/1000)/1000 -> 1.1581422
L29: 44077 | M29: 73368 | N29: 68940 | O29: =M29-N29 -> 4428 | P29: =1.5*24*30 -> 1080 | Q29: =O29-P29 -> 3348 | R29: 0.996 | S29: =(P29/M29)*100 -> 1.4720314 | T29: =(Q29/M29)*100 -> 4.5632974 | U29: 388 | V29: =(U29/1250) -> 0.3104 | W29: =+((3*37.87*V29*37.87*V29*0.882*1.5)+(3*1667*V29*1667*V29*0.596)/1000)/1000 -> 1.027143
L30: 44109 | M30: 48336 | N30: 45110 | O30: =M30-N30 -> 3226 | P30: =1.5*24*31 -> 1116 | Q30: =O30-P30 -> 2110 | R30: 0.996 | S30: =(P30/M30)*100 -> 2.3088381 | T30: =(Q30/M30)*100 -> 4.3652764 | U30: 274 | V30: =(U30/1250) -> 0.2192 | W30: =+((3*37.87*V30*37.87*V30*0.882*1.5)+(3*1667*V30*1667*V30*0.596)/1000)/1000 -> 0.5122342
L31: 44141 | M31: 45360 | N31: 42010 | O31: =M31-N31 -> 3350 | P31: =1.5*24*31 -> 1116 | Q31: =O31-P31 -> 2234 | R31: 0.996 | S31: =(P31/M31)*100 -> 2.4603175 | T31: =(Q31/M31)*100 -> 4.9250441 | U31: 455 | V31: =(U31/1250) -> 0.364 | W31: =+((3*37.87*V31*37.87*V31*0.882*1.5)+(3*1667*V31*1667*V31*0.596)/1000)/1000 -> 1.4125058
B35: Transformer full Load cu losses is per hour 12.5 Unit/KWH - Confirm by Transformer manufacturer | K35: Capacitor Bank Operational Unit Looses
B36: Transformer fixed losses/Iron losses is per hour 1.5 Unit/KWH - Confirm by Transformer manufacturer. | K36: Month | L36: Ellora Capacitor Bank Capacity (KVA) | M36: Fixed/Continously ON Capacitor Bank Capacity(KVA) | N36: Variable Capacitor Bank Capacity(KVA) | O36: As per Manufecturer Per KVR KW Looses | P36: Variable Capacitor Bank Per day uses in % | Q36: Variable Capacitor Bank Per Hrs. Uses in KVA | R36: Variable Capacitor Bank Per Day Uses in KVA | T36: No of Days of that Month | U36: Capacitor Bank Monthly Operational Unit Looses | X36: Unit Reading As Per Capacitor Bank Unit KWH Meter | Y36: Difference Between Capacitor Bank Meter Unit and OEM Calculated Capacitor Bank Operational Unit | Z36: Difference Between Capacitor Bank Meter Unit and LT Panel Unit Looses | AA36: Difference Between LT Panel Unit Looses and OEM Calculation Unit (Non - identified Load Losses)
B37: Maximum is recorded on Power supply Agency, when a load run for minimum 30 minutes. | R37: Hrs. | S37: Variable Capacitor Bank Per Day Uses in KVA | U37: Variable Capacitor Monthly KW Looses | V37: Fixed Capacitor Monthly KW Losses | W37: Total Unit Looses For using of Capacitor Bank
B38: Transformer given maximum efficiency when no load loos equal to cu loss. | K38: 43556 | L38: 419 | M38: 50 | N38: =L38-M38 -> 369 | O38: =0.45/1000 -> 0.00045 | P38: 0.8 | Q38: =N38*P38 -> 295.2 | R38: 12 | S38: =Q38*R38 -> 3542.4 | T38: 30 | U38: =S38*T38*O38 -> 47.8224 | V38: =M38*O38*24*T38 -> 16.2 | W38: =U38+V38 -> 64.0224 | X38: 1458 | Y38: =X38-W38 -> 1393.9776 | Z38: =X38-O5 -> 1053 | AA38: =O5-W38 -> 340.9776
B39: Transformer % of Losses should be ≤3% of monthly unit value. | K39: 43586 | L39: 419 | M39: 50 | N39: =L39-M39 -> 369 | O39: =0.45/1000 -> 0.00045 | P39: 0.8 | Q39: =N39*P39 -> 295.2 | R39: 12 | S39: =Q39*R39 -> 3542.4 | T39: 31 | U39: =S39*T39*O39 -> 49.41648 | V39: =M39*O39*24*T39 -> 16.74 | W39: =U39+V39 -> 66.15648 | X39: 774 | Y39: =X39-W39 -> 707.84352 | Z39: =X39-O6 -> 124 | AA39: =O6-W39 -> 583.84352
K40: 43617 | L40: 419 | M40: 50 | N40: =L40-M40 -> 369 | O40: =0.45/1000 -> 0.00045 | P40: 0.8 | Q40: =N40*P40 -> 295.2 | R40: 12 | S40: =Q40*R40 -> 3542.4 | T40: 30 | U40: =S40*T40*O40 -> 47.8224 | V40: =M40*O40*24*T40 -> 16.2 | W40: =U40+V40 -> 64.0224 | X40: 894 | Y40: =X40-W40 -> 829.9776 | Z40: =X40-O7 -> 176 | AA40: =O7-W40 -> 653.9776
B41: Capacitor Bank Operational Unit Losses | K41: 43647 | L41: 419 | M41: 50 | N41: =L41-M41 -> 369 | O41: =0.45/1000 -> 0.00045 | P41: 0.8 | Q41: =N41*P41 -> 295.2 | R41: 12 | S41: =Q41*R41 -> 3542.4 | T41: 31 | U41: =S41*T41*O41 -> 49.41648 | V41: =M41*O41*24*T41 -> 16.74 | W41: =U41+V41 -> 66.15648 | X41: 732 | Y41: =X41-W41 -> 665.84352 | Z41: =X41-O8 -> -242 | AA41: =O8-W41 -> 907.84352
B42: Note - Fixed/continously ON Capacitor capacity is the 5% of Transformer capacity. | K42: 43678 | L42: 419 | M42: 50 | N42: =L42-M42 -> 369 | O42: =0.45/1000 -> 0.00045 | P42: 0.8 | Q42: =N42*P42 -> 295.2 | R42: 12 | S42: =Q42*R42 -> 3542.4 | T42: 31 | U42: =S42*T42*O42 -> 49.41648 | V42: =M42*O42*24*T42 -> 16.74 | W42: =U42+V42 -> 66.15648 | X42: 582 | Y42: =X42-W42 -> 515.84352 | Z42: =X42-O9 -> -1493 | AA42: =O9-W42 -> 2008.8435
K43: 44013 | L43: 419 | M43: 50 | N43: =L43-M43 -> 369 | O43: =0.45/1000 -> 0.00045 | P43: 0.8 | Q43: =N43*P43 -> 295.2 | R43: 12 | S43: =Q43*R43 -> 3542.4 | T43: 31 | U43: =S43*T43*O43 -> 49.41648 | V43: =M43*O43*24*T43 -> 16.74 | W43: =U43+V43 -> 66.15648 | X43: 306 | Y43: =X43-W43 -> 239.84352 | Z43: =X43-O10 -> 196 | AA43: =O10-W43 -> 43.84352
K44: 44044 | L44: 419 | M44: 50 | N44: =L44-M44 -> 369 | O44: =0.45/1000 -> 0.00045 | P44: 0.8 | Q44: =N44*P44 -> 295.2 | R44: 12 | S44: =Q44*R44 -> 3542.4 | T44: 31 | U44: =S44*T44*O44 -> 49.41648 | V44: =M44*O44*24*T44 -> 16.74 | W44: =U44+V44 -> 66.15648 | X44: 2274 | Y44: =X44-W44 -> 2207.8435 | Z44: =X44-O11 -> 1924 | AA44: =O11-W44 -> 283.84352
K45: 44075 | L45: 419 | M45: 50 | N45: =L45-M45 -> 369 | O45: =0.45/1000 -> 0.00045 | P45: 0.8 | Q45: =N45*P45 -> 295.2 | R45: 12 | S45: =Q45*R45 -> 3542.4 | T45: 30 | U45: =S45*T45*O45 -> 47.8224 | V45: =M45*O45*24*T45 -> 16.2 | W45: =U45+V45 -> 64.0224 | X45: 4428 | Y45: =X45-W45 -> 4363.9776 | Z45: =X45-O12 -> 4048 | AA45: =O12-W45 -> 315.9776
K46: 44105 | L46: 419 | M46: 50 | N46: =L46-M46 -> 369 | O46: =0.45/1000 -> 0.00045 | P46: 0.8 | Q46: =N46*P46 -> 295.2 | R46: 12 | S46: =Q46*R46 -> 3542.4 | T46: 31 | U46: =S46*T46*O46 -> 49.41648 | V46: =M46*O46*24*T46 -> 16.74 | W46: =U46+V46 -> 66.15648 | X46: 504 | Y46: =X46-W46 -> 437.84352 | Z46: =X46-O13 -> 784 | AA46: =O13-W46 -> -346.15648
K47: 44136 | L47: 419 | M47: 50 | N47: =L47-M47 -> 369 | O47: =0.45/1000 -> 0.00045 | P47: 0.8 | Q47: =N47*P47 -> 295.2 | R47: 12 | S47: =Q47*R47 -> 3542.4 | T47: 30 | U47: =S47*T47*O47 -> 47.8224 | V47: =M47*O47*24*T47 -> 16.2 | W47: =U47+V47 -> 64.0224 | X47: 1278 | Y47: =X47-W47 -> 1213.9776 | Z47: =X47-O14 -> 615 | AA47: =O14-W47 -> 598.9776

Sheet Meterwise Billing Details
A1: Unit Consumption of Different Energy Meter Billed To Customer Account Used by Production Team
A3: Day | B3: Meter Name - Hospital LT With Makeup Room 201,202 & 203 | D3: Meter Name - Hospital Out Door | F3: Meter Name -Bungalow 1 LT | H3: Meter Name - Bungalow 1 Out Door | J3: Meter Name - Office Set | L3: Meter Name - Police Station | N3: Meter Name - 8000 sqft | P3: Meter Name - Restaurant | R3: Meter Name - Parsi Bungalow AC | T3: Meter Name - Parsi Bungalow Light | V3: Meter Name - Bungalow 2 LT | X3: Meter Name - Bungalow 2 Makeup Room | Z3: Meter Name - Villa Set AC | AB3: Meter Name - Villa Set Light | AD3: Meter Name - Villa Set Out Door | AF3: Meter Name - Road Light | AH3: Meter Name - Hill
B4: Production Name | C4: Unit | D4: Production Name | E4: Unit | F4: Production Name | G4: Unit | H4: Production Name | I4: Unit | J4: Production Name | K4: Unit | L4: Production Name | M4: Unit | N4: Production Name | O4: Unit | P4: Production Name | Q4: Unit | R4: Production Name | S4: Unit | T4: Production Name | U4: Unit | V4: Production Name | W4: Unit | X4: Production Name | Y4: Unit | Z4: Production Name | AA4: Unit | AB4: Production Name | AC4: Unit | AD4: Production Name | AE4: Unit | AF4: Production Name | AG4: Unit | AH4: Production Name | AI4: Unit
A5: 1 | B5: =IF(AND(Hospital!R4=Hospital!$B$40,(Hospital!AJ4>0)),Hospital!T4,"") -> Bambai Dreams Entertainment (Opc) Private Limited | C5: =Hospital!AJ4 -> 368 | D5: =IF(AND(Hospital!BD4=Hospital!$B$40,(Hospital!BV4>0)),Hospital!BF4,"") | E5: =Hospital!BV4 -> 0 | F5: =IF(AND('Bungalow 1'!R4='Bungalow 1'!$B$40,('Bungalow 1'!AJ4>0)),'Bungalow 1'!T4,"") -> Classic Films | G5: ='Bungalow 1'!AJ4 -> 692 | H5: =IF(AND('Bungalow 1'!BD4='Bungalow 1'!$B$40,('Bungalow 1'!BV4>0)),'Bungalow 1'!BF4,"") | I5: ='Bungalow 1'!BV4 -> 0 | J5: =IF(AND('Office Set'!R3='Office Set'!$B$39,('Office Set'!AJ3>0)),'Office Set'!T3,"") | K5: ='Office Set'!AJ3 -> 0 | L5: =IF(AND('Police Station'!R4='Police Station'!$B$40,('Police Station'!AJ4>0)),'Police Station'!T4,"") | M5: ='Police Station'!AJ4 -> 0 | N5: =IF(AND('8000 sqft'!R4='8000 sqft'!$B$40,('8000 sqft'!AJ4>0)),'8000 sqft'!T4,"") | O5: ='8000 sqft'!AJ4 -> 0 | P5: =IF(AND('Restaurant '!R4='Restaurant '!$B$40,('Restaurant '!AJ4>0)),'Restaurant '!T4,"") | Q5: ='Restaurant '!AJ4 -> 0 | R5: =IF(AND('Parsi Bungalow'!Y4='Parsi Bungalow'!$B$40,('Parsi Bungalow'!AQ4>0)),'Parsi Bungalow'!AA4,"") | S5: ='Parsi Bungalow'!AQ4 -> 0 | T5: =IF(AND('Parsi Bungalow'!BK4='Parsi Bungalow'!$B$40,('Parsi Bungalow'!CC4>0)),'Parsi Bungalow'!BM4,"") | U5: ='Parsi Bungalow'!CC4 -> 0 | V5: =IF(AND('Bungalow 2'!R4='Bungalow 2'!$B$40,('Bungalow 2'!AJ4>0)),'Bungalow 2'!T4,"") | W5: ='Bungalow 2'!AJ4 -> 0 | X5: =IF(AND('Bungalow 2'!BD4='Bungalow 2'!$B$40,('Bungalow 2'!BV4>0)),'Bungalow 2'!BF4,"") | Y5: ='Bungalow 2'!BV4 -> 0 | Z5: =IF(AND('Villa Set '!Y4='Villa Set '!$B$40,('Villa Set '!AQ4>0)),'Villa Set '!AA4,"") -> Sabir Khan Films Private Limited | AA5: ='Villa Set '!AQ4 -> 836 | AB5: =IF(AND('Villa Set '!BK4='Villa Set '!$B$40,('Villa Set '!CC4>0)),'Villa Set '!BM4,"") -> Sabir Khan Films Private Limited | AC5: ='Villa Set '!CC4 -> 168 | AD5: =IF(AND('Villa Set '!CW4='Villa Set '!$B$40,('Villa Set '!DO4>0)),'Villa Set '!CY4,"") | AE5: ='Villa Set '!DO4 -> 0 | AF5: =IF('Road Light'!R4>0,'Road Light'!M4,"") | AG5: ='Road Light'!R4 -> 0 | AH5: =IF(AND(Hill!R4=Hill!$B$40,(Hill!AJ4>0)),Hill!T4,"") | AI5: =Hill!AJ4 -> 0
A6: 2 | B6: =IF(AND(Hospital!R5=Hospital!$B$40,(Hospital!AJ5>0)),Hospital!T5,"") | C6: =Hospital!AJ5 -> 0 | D6: =IF(AND(Hospital!BD5=Hospital!$B$40,(Hospital!BV5>0)),Hospital!BF5,"") | E6: =Hospital!BV5 -> 0 | F6: =IF(AND('Bungalow 1'!R5='Bungalow 1'!$B$40,('Bungalow 1'!AJ5>0)),'Bungalow 1'!T5,"") -> Rohan Paresh Pujara | G6: ='Bungalow 1'!AJ5 -> 606 | H6: =IF(AND('Bungalow 1'!BD5='Bungalow 1'!$B$40,('Bungalow 1'!BV5>0)),'Bungalow 1'!BF5,"") | I6: ='Bungalow 1'!BV5 -> 0 | J6: =IF(AND('Office Set'!R4='Office Set'!$B$39,('Office Set'!AJ4>0)),'Office Set'!T4,"") | K6: ='Office Set'!AJ4 -> 0 | L6: =IF(AND('Police Station'!R5='Police Station'!$B$40,('Police Station'!AJ5>0)),'Police Station'!T5,"") | M6: ='Police Station'!AJ5 -> 0 | N6: =IF(AND('8000 sqft'!R5='8000 sqft'!$B$40,('8000 sqft'!AJ5>0)),'8000 sqft'!T5,"") | O6: ='8000 sqft'!AJ5 -> 0 | P6: =IF(AND('Restaurant '!R5='Restaurant '!$B$40,('Restaurant '!AJ5>0)),'Restaurant '!T5,"") | Q6: ='Restaurant '!AJ5 -> 0 | R6: =IF(AND('Parsi Bungalow'!Y5='Parsi Bungalow'!$B$40,('Parsi Bungalow'!AQ5>0)),'Parsi Bungalow'!AA5,"") | S6: ='Parsi Bungalow'!AQ5 -> 0 | T6: =IF(AND('Parsi Bungalow'!BK5='Parsi Bungalow'!$B$40,('Parsi Bungalow'!CC5>0)),'Parsi Bungalow'!BM5,"") | U6: ='Parsi Bungalow'!CC5 -> 0 | V6: =IF(AND('Bungalow 2'!R5='Bungalow 2'!$B$40,('Bungalow 2'!AJ5>0)),'Bungalow 2'!T5,"") | W6: ='Bungalow 2'!AJ5 -> 0 | X6: =IF(AND('Bungalow 2'!BD5='Bungalow 2'!$B$40,('Bungalow 2'!BV5>0)),'Bungalow 2'!BF5,"") | Y6: ='Bungalow 2'!BV5 -> 0 | Z6: =IF(AND('Villa Set '!Y5='Villa Set '!$B$40,('Villa Set '!AQ5>0)),'Villa Set '!AA5,"") -> Sabir Khan Films Private Limited | AA6: ='Villa Set '!AQ5 -> 529 | AB6: =IF(AND('Villa Set '!BK5='Villa Set '!$B$40,('Villa Set '!CC5>0)),'Villa Set '!BM5,"") -> Sabir Khan Films Private Limited | AC6: ='Villa Set '!CC5 -> 129 | AD6: =IF(AND('Villa Set '!CW5='Villa Set '!$B$40,('Villa Set '!DO5>0)),'Villa Set '!CY5,"") | AE6: ='Villa Set '!DO5 -> 0 | AG6: ='Road Light'!R5 -> 0 | AH6: =IF(AND(Hill!R5=Hill!$B$40,(Hill!AJ5>0)),Hill!T5,"") | AI6: =Hill!AJ5 -> 0
A7: 3 | B7: =IF(AND(Hospital!R6=Hospital!$B$40,(Hospital!AJ6>0)),Hospital!T6,"") -> Sabir Khan Films Private Limited | C7: =Hospital!AJ6 -> 227 | D7: =IF(AND(Hospital!BD6=Hospital!$B$40,(Hospital!BV6>0)),Hospital!BF6,"") | E7: =Hospital!BV6 -> 0 | F7: =IF(AND('Bungalow 1'!R6='Bungalow 1'!$B$40,('Bungalow 1'!AJ6>0)),'Bungalow 1'!T6,"") -> Sabir Khan Films Private Limited | G7: ='Bungalow 1'!AJ6 -> 7 | H7: =IF(AND('Bungalow 1'!BD6='Bungalow 1'!$B$40,('Bungalow 1'!BV6>0)),'Bungalow 1'!BF6,"") | I7: ='Bungalow 1'!BV6 -> 0 | J7: =IF(AND('Office Set'!R5='Office Set'!$B$39,('Office Set'!AJ5>0)),'Office Set'!T5,"") | K7: ='Office Set'!AJ5 -> 0 | L7: =IF(AND('Police Station'!R6='Police Station'!$B$40,('Police Station'!AJ6>0)),'Police Station'!T6,"") | M7: ='Police Station'!AJ6 -> 0 | N7: =IF(AND('8000 sqft'!R6='8000 sqft'!$B$40,('8000 sqft'!AJ6>0)),'8000 sqft'!T6,"") | O7: ='8000 sqft'!AJ6 -> 0 | P7: =IF(AND('Restaurant '!R6='Restaurant '!$B$40,('Restaurant '!AJ6>0)),'Restaurant '!T6,"") -> Flying Elephant Studios Pvt.Ltd. | Q7: ='Restaurant '!AJ6 -> 559 | R7: =IF(AND('Parsi Bungalow'!Y6='Parsi Bungalow'!$B$40,('Parsi Bungalow'!AQ6>0)),'Parsi Bungalow'!AA6,"") | S7: ='Parsi Bungalow'!AQ6 -> 0 | T7: =IF(AND('Parsi Bungalow'!BK6='Parsi Bungalow'!$B$40,('Parsi Bungalow'!CC6>0)),'Parsi Bungalow'!BM6,"") | U7: ='Parsi Bungalow'!CC6 -> 0 | V7: =IF(AND('Bungalow 2'!R6='Bungalow 2'!$B$40,('Bungalow 2'!AJ6>0)),'Bungalow 2'!T6,"") | W7: ='Bungalow 2'!AJ6 -> 0 | X7: =IF(AND('Bungalow 2'!BD6='Bungalow 2'!$B$40,('Bungalow 2'!BV6>0)),'Bungalow 2'!BF6,"") | Y7: ='Bungalow 2'!BV6 -> 0 | Z7: =IF(AND('Villa Set '!Y6='Villa Set '!$B$40,('Villa Set '!AQ6>0)),'Villa Set '!AA6,"") | AA7: ='Villa Set '!AQ6 -> 0 | AB7: =IF(AND('Villa Set '!BK6='Villa Set '!$B$40,('Villa Set '!CC6>0)),'Villa Set '!BM6,"") -> Sabir Khan Films Private Limited | AC7: ='Villa Set '!CC6 -> 119 | AD7: =IF(AND('Villa Set '!CW6='Villa Set '!$B$40,('Villa Set '!DO6>0)),'Villa Set '!CY6,"") | AE7: ='Villa Set '!DO6 -> 0 | AG7: ='Road Light'!R6 -> 0 | AH7: =IF(AND(Hill!R6=Hill!$B$40,(Hill!AJ6>0)),Hill!T6,"") | AI7: =Hill!AJ6 -> 0
A8: 4 | B8: =IF(AND(Hospital!R7=Hospital!$B$40,(Hospital!AJ7>0)),Hospital!T7,"") | C8: =Hospital!AJ7 -> 0 | D8: =IF(AND(Hospital!BD7=Hospital!$B$40,(Hospital!BV7>0)),Hospital!BF7,"") | E8: =Hospital!BV7 -> 0 | F8: =IF(AND('Bungalow 1'!R7='Bungalow 1'!$B$40,('Bungalow 1'!AJ7>0)),'Bungalow 1'!T7,"") | G8: ='Bungalow 1'!AJ7 -> 0 | H8: =IF(AND('Bungalow 1'!BD7='Bungalow 1'!$B$40,('Bungalow 1'!BV7>0)),'Bungalow 1'!BF7,"") | I8: ='Bungalow 1'!BV7 -> 0 | J8: =IF(AND('Office Set'!R6='Office Set'!$B$39,('Office Set'!AJ6>0)),'Office Set'!T6,"") | K8: ='Office Set'!AJ6 -> 0 | L8: =IF(AND('Police Station'!R7='Police Station'!$B$40,('Police Station'!AJ7>0)),'Police Station'!T7,"") | M8: ='Police Station'!AJ7 -> 0 | N8: =IF(AND('8000 sqft'!R7='8000 sqft'!$B$40,('8000 sqft'!AJ7>0)),'8000 sqft'!T7,"") | O8: ='8000 sqft'!AJ7 -> 0 | P8: =IF(AND('Restaurant '!R7='Restaurant '!$B$40,('Restaurant '!AJ7>0)),'Restaurant '!T7,"") | Q8: ='Restaurant '!AJ7 -> 0 | R8: =IF(AND('Parsi Bungalow'!Y7='Parsi Bungalow'!$B$40,('Parsi Bungalow'!AQ7>0)),'Parsi Bungalow'!AA7,"") | S8: ='Parsi Bungalow'!AQ7 -> 0 | T8: =IF(AND('Parsi Bungalow'!BK7='Parsi Bungalow'!$B$40,('Parsi Bungalow'!CC7>0)),'Parsi Bungalow'!BM7,"") | U8: ='Parsi Bungalow'!CC7 -> 0 | V8: =IF(AND('Bungalow 2'!R7='Bungalow 2'!$B$40,('Bungalow 2'!AJ7>0)),'Bungalow 2'!T7,"") | W8: ='Bungalow 2'!AJ7 -> 0 | X8: =IF(AND('Bungalow 2'!BD7='Bungalow 2'!$B$40,('Bungalow 2'!BV7>0)),'Bungalow 2'!BF7,"") | Y8: ='Bungalow 2'!BV7 -> 0 | Z8: =IF(AND('Villa Set '!Y7='Villa Set '!$B$40,('Villa Set '!AQ7>0)),'Villa Set '!AA7,"") | AA8: ='Villa Set '!AQ7 -> 0 | AB8: =IF(AND('Villa Set '!BK7='Villa Set '!$B$40,('Villa Set '!CC7>0)),'Villa Set '!BM7,"") | AC8: ='Villa Set '!CC7 -> 0 | AD8: =IF(AND('Villa Set '!CW7='Villa Set '!$B$40,('Villa Set '!DO7>0)),'Villa Set '!CY7,"") | AE8: ='Villa Set '!DO7 -> 0 | AG8: ='Road Light'!R7 -> 0 | AH8: =IF(AND(Hill!R7=Hill!$B$40,(Hill!AJ7>0)),Hill!T7,"") | AI8: =Hill!AJ7 -> 0
A9: 5 | B9: =IF(AND(Hospital!R8=Hospital!$B$40,(Hospital!AJ8>0)),Hospital!T8,"") -> White Rivers Media Solutions Private Limited | C9: =Hospital!AJ8 -> 506 | D9: =IF(AND(Hospital!BD8=Hospital!$B$40,(Hospital!BV8>0)),Hospital!BF8,"") | E9: =Hospital!BV8 -> 0 | F9: =IF(AND('Bungalow 1'!R8='Bungalow 1'!$B$40,('Bungalow 1'!AJ8>0)),'Bungalow 1'!T8,"") | G9: ='Bungalow 1'!AJ8 -> 0 | H9: =IF(AND('Bungalow 1'!BD8='Bungalow 1'!$B$40,('Bungalow 1'!BV8>0)),'Bungalow 1'!BF8,"") | I9: ='Bungalow 1'!BV8 -> 0 | J9: =IF(AND('Office Set'!R7='Office Set'!$B$39,('Office Set'!AJ7>0)),'Office Set'!T7,"") | K9: ='Office Set'!AJ7 -> 0 | L9: =IF(AND('Police Station'!R8='Police Station'!$B$40,('Police Station'!AJ8>0)),'Police Station'!T8,"") | M9: ='Police Station'!AJ8 -> 0 | N9: =IF(AND('8000 sqft'!R8='8000 sqft'!$B$40,('8000 sqft'!AJ8>0)),'8000 sqft'!T8,"") | O9: ='8000 sqft'!AJ8 -> 0 | P9: =IF(AND('Restaurant '!R8='Restaurant '!$B$40,('Restaurant '!AJ8>0)),'Restaurant '!T8,"") -> Vijaya Entertainment India | Q9: ='Restaurant '!AJ8 -> 1 | R9: =IF(AND('Parsi Bungalow'!Y8='Parsi Bungalow'!$B$40,('Parsi Bungalow'!AQ8>0)),'Parsi Bungalow'!AA8,"") | S9: ='Parsi Bungalow'!AQ8 -> 0 | T9: =IF(AND('Parsi Bungalow'!BK8='Parsi Bungalow'!$B$40,('Parsi Bungalow'!CC8>0)),'Parsi Bungalow'!BM8,"") | U9: ='Parsi Bungalow'!CC8 -> 0 | V9: =IF(AND('Bungalow 2'!R8='Bungalow 2'!$B$40,('Bungalow 2'!AJ8>0)),'Bungalow 2'!T8,"") | W9: ='Bungalow 2'!AJ8 -> 0 | X9: =IF(AND('Bungalow 2'!BD8='Bungalow 2'!$B$40,('Bungalow 2'!BV8>0)),'Bungalow 2'!BF8,"") | Y9: ='Bungalow 2'!BV8 -> 0 | Z9: =IF(AND('Villa Set '!Y8='Villa Set '!$B$40,('Villa Set '!AQ8>0)),'Villa Set '!AA8,"") -> Vijaya Entertainment India | AA9: ='Villa Set '!AQ8 -> 403 | AB9: =IF(AND('Villa Set '!BK8='Villa Set '!$B$40,('Villa Set '!CC8>0)),'Villa Set '!BM8,"") -> Vijaya Entertainment India | AC9: ='Villa Set '!CC8 -> 520 | AD9: =IF(AND('Villa Set '!CW8='Villa Set '!$B$40,('Villa Set '!DO8>0)),'Villa Set '!CY8,"") | AE9: ='Villa Set '!DO8 -> 0 | AG9: ='Road Light'!R8 -> 0 | AH9: =IF(AND(Hill!R8=Hill!$B$40,(Hill!AJ8>0)),Hill!T8,"") | AI9: =Hill!AJ8 -> 0
A10: 6 | B10: =IF(AND(Hospital!R9=Hospital!$B$40,(Hospital!AJ9>0)),Hospital!T9,"") -> Superfly Films Private Limited | C10: =Hospital!AJ9 -> 19 | D10: =IF(AND(Hospital!BD9=Hospital!$B$40,(Hospital!BV9>0)),Hospital!BF9,"") | E10: =Hospital!BV9 -> 0 | F10: =IF(AND('Bungalow 1'!R9='Bungalow 1'!$B$40,('Bungalow 1'!AJ9>0)),'Bungalow 1'!T9,"") | G10: ='Bungalow 1'!AJ9 -> 0 | H10: =IF(AND('Bungalow 1'!BD9='Bungalow 1'!$B$40,('Bungalow 1'!BV9>0)),'Bungalow 1'!BF9,"") | I10: ='Bungalow 1'!BV9 -> 0 | J10: =IF(AND('Office Set'!R8='Office Set'!$B$39,('Office Set'!AJ8>0)),'Office Set'!T8,"") | K10: ='Office Set'!AJ8 -> 0 | L10: =IF(AND('Police Station'!R9='Police Station'!$B$40,('Police Station'!AJ9>0)),'Police Station'!T9,"") | M10: ='Police Station'!AJ9 -> 0 | N10: =IF(AND('8000 sqft'!R9='8000 sqft'!$B$40,('8000 sqft'!AJ9>0)),'8000 sqft'!T9,"") | O10: ='8000 sqft'!AJ9 -> 0 | P10: =IF(AND('Restaurant '!R9='Restaurant '!$B$40,('Restaurant '!AJ9>0)),'Restaurant '!T9,"") -> High Rise Films Private Limited | Q10: ='Restaurant '!AJ9 -> 370 | R10: =IF(AND('Parsi Bungalow'!Y9='Parsi Bungalow'!$B$40,('Parsi Bungalow'!AQ9>0)),'Parsi Bungalow'!AA9,"") -> High Rise Films Private Limited | S10: ='Parsi Bungalow'!AQ9 -> 967 | T10: =IF(AND('Parsi Bungalow'!BK9='Parsi Bungalow'!$B$40,('Parsi Bungalow'!CC9>0)),'Parsi Bungalow'!BM9,"") -> High Rise Films Private Limited | U10: ='Parsi Bungalow'!CC9 -> 557 | V10: =IF(AND('Bungalow 2'!R9='Bungalow 2'!$B$40,('Bungalow 2'!AJ9>0)),'Bungalow 2'!T9,"") -> Four Lions Films Private Limited | W10: ='Bungalow 2'!AJ9 -> 60 | X10: =IF(AND('Bungalow 2'!BD9='Bungalow 2'!$B$40,('Bungalow 2'!BV9>0)),'Bungalow 2'!BF9,"") | Y10: ='Bungalow 2'!BV9 -> 0 | Z10: =IF(AND('Villa Set '!Y9='Villa Set '!$B$40,('Villa Set '!AQ9>0)),'Villa Set '!AA9,"") | AA10: ='Villa Set '!AQ9 -> 0 | AB10: =IF(AND('Villa Set '!BK9='Villa Set '!$B$40,('Villa Set '!CC9>0)),'Villa Set '!BM9,"") | AC10: ='Villa Set '!CC9 -> 0 | AD10: =IF(AND('Villa Set '!CW9='Villa Set '!$B$40,('Villa Set '!DO9>0)),'Villa Set '!CY9,"") | AE10: ='Villa Set '!DO9 -> 0 | AG10: ='Road Light'!R9 -> 0 | AH10: =IF(AND(Hill!R9=Hill!$B$40,(Hill!AJ9>0)),Hill!T9,"") | AI10: =Hill!AJ9 -> 0
A11: 7 | B11: =IF(AND(Hospital!R10=Hospital!$B$40,(Hospital!AJ10>0)),Hospital!T10,"") -> Superfly Films Private Limited | C11: =Hospital!AJ10 -> 281 | D11: =IF(AND(Hospital!BD10=Hospital!$B$40,(Hospital!BV10>0)),Hospital!BF10,"") | E11: =Hospital!BV10 -> 0 | F11: =IF(AND('Bungalow 1'!R10='Bungalow 1'!$B$40,('Bungalow 1'!AJ10>0)),'Bungalow 1'!T10,"") | G11: ='Bungalow 1'!AJ10 -> 0 | H11: =IF(AND('Bungalow 1'!BD10='Bungalow 1'!$B$40,('Bungalow 1'!BV10>0)),'Bungalow 1'!BF10,"") | I11: ='Bungalow 1'!BV10 -> 0 | J11: =IF(AND('Office Set'!R9='Office Set'!$B$39,('Office Set'!AJ9>0)),'Office Set'!T9,"") | K11: ='Office Set'!AJ9 -> 0 | L11: =IF(AND('Police Station'!R10='Police Station'!$B$40,('Police Station'!AJ10>0)),'Police Station'!T10,"") | M11: ='Police Station'!AJ10 -> 0 | N11: =IF(AND('8000 sqft'!R10='8000 sqft'!$B$40,('8000 sqft'!AJ10>0)),'8000 sqft'!T10,"") | O11: ='8000 sqft'!AJ10 -> 0 | P11: =IF(AND('Restaurant '!R10='Restaurant '!$B$40,('Restaurant '!AJ10>0)),'Restaurant '!T10,"") | Q11: ='Restaurant '!AJ10 -> 0 | R11: =IF(AND('Parsi Bungalow'!Y10='Parsi Bungalow'!$B$40,('Parsi Bungalow'!AQ10>0)),'Parsi Bungalow'!AA10,"") | S11: ='Parsi Bungalow'!AQ10 -> 0 | T11: =IF(AND('Parsi Bungalow'!BK10='Parsi Bungalow'!$B$40,('Parsi Bungalow'!CC10>0)),'Parsi Bungalow'!BM10,"") | U11: ='Parsi Bungalow'!CC10 -> 0 | V11: =IF(AND('Bungalow 2'!R10='Bungalow 2'!$B$40,('Bungalow 2'!AJ10>0)),'Bungalow 2'!T10,"") -> Rising Star | W11: ='Bungalow 2'!AJ10 -> 67 | X11: =IF(AND('Bungalow 2'!BD10='Bungalow 2'!$B$40,('Bungalow 2'!BV10>0)),'Bungalow 2'!BF10,"") | Y11: ='Bungalow 2'!BV10 -> 0 | Z11: =IF(AND('Villa Set '!Y10='Villa Set '!$B$40,('Villa Set '!AQ10>0)),'Villa Set '!AA10,"") | AA11: ='Villa Set '!AQ10 -> 0 | AB11: =IF(AND('Villa Set '!BK10='Villa Set '!$B$40,('Villa Set '!CC10>0)),'Villa Set '!BM10,"") | AC11: ='Villa Set '!CC10 -> 0 | AD11: =IF(AND('Villa Set '!CW10='Villa Set '!$B$40,('Villa Set '!DO10>0)),'Villa Set '!CY10,"") | AE11: ='Villa Set '!DO10 -> 0 | AG11: ='Road Light'!R10 -> 0 | AH11: =IF(AND(Hill!R10=Hill!$B$40,(Hill!AJ10>0)),Hill!T10,"") | AI11: =Hill!AJ10 -> 0
